Workbook

Sheet MENU RAPEL 3 HARI
A1: MENU
A2: 9-11 MARET | C2: 12-14 MARET | E2: 15-17 MARET | G2: 18-20 MARET
A3: KECIL | B3: BESAR | C3: KECIL | D3: BESAR | E3: KECIL | F3: BESAR | G3: KECIL | H3: BESAR
A4: roti 3 | B4: roti 3 | C4: jagung rebus 1 pcs (potong jd 2) | D4: Jagung rebus 1 1/2 | E4: Goguma Bread 2 | F4: Goguma bread 2 | G4: Bolen pisang 3pcs | H4: Bolen pisang 3pcs
A5: ayam kuning 3 potong | B5: ayam kuning 3 potong | C5: Ikan lele goreng 2 | D5: ikan lele goreng 2 | E5: ayam bumbu kuning 2 | F5: ayam bumbu kuning 2 | G5: ayam goreng 2 pcs | H5: ayam goreng 2 pcs
A6: tahu bumbu kuning 2pcs | B6: tahu bumbu kunging 2pcs | C6: Telur ayam 1 | D6: Telur ayam 1 | E6: Tahu bakso 2 | F6: Tahu Bakso 2 | G6: Telur ayam rebus 1 | H6: telur ayam rebus 1
A7: tempe bumbu kuning 1pcs | B7: tempe bumbu kuning 1pcs | C7: tempe bacem 3pcs | D7: tempe bacem 3pcs | E7: puding wortel 1 | F7: puding wortel 1 | G7: tahu goreng 3 | H7: tahu goreng 3
A8: sari kacang hijau 2pcs | B8: Sari Kacanng Hijau 2 | C8: puding labu kuning 1 | D8: puding labu kuning 1 | E8: sari kacang hijau 2pcs | F8: sari kacang hijau 2pcs | G8: puding wortel 1 | H8: puding wortel 1
A9: alpukat 1 | B9: alpukat 1 | C9: susu 115 2pcs | D9: susu 225 1pcs | E9: alpukat 1 | F9: manggis 1 | G9: susu 115 2pcs | H9: susu 225 ml 1pcs
A10: Jeruk 1 | B10: Manggis 1 | C10: pisang 2 | D10: pisang 2 | E10: Jeruk 2 | F10: alpukat 1 | G10: markisa 1 | H10: maarkisa 1
A11: markisa 1 | B11: markisa 1 | C11: kelengkeng 10 | D11: kelengkeng 10 | F11: Jeruk 1 | G11: pisang sunpride 1 | H11: pisang sunpride 1
D12: kurma 10 | G12: kelengkeng 10 | H12: kelengkeng 10
H13: kurma 10 butir
B15: MANTAP NII
A17: MENU
A18: Senin 09/03/26 | C18: Selasa 10/03/26 | E18: Rabu 11/03/26 | G18: Kamis 12/03/26 | I18: Jumat 13/03/26 | K18: Sabtu 14/03/26
A19: KECIL | B19: BESAR | C19: KECIL | D19: BESAR | E19: KECIL | F19: BESAR | G19: KECIL | H19: BESAR | I19: KECIL | J19: BESAR | K19: KECIL | L19: BESAR
A20: ayam kuning 1 potong | B20: ayam kuning 1 potong | C20: Roti abon | D20: roti abon | E20: roti pizza | F20: roti pizza | G20: Telur ayam rebus 1 | H20: Telur ayam rebus 1 | I20: Roti | J20: Roti | K20: roti | L20: roti
A21: tahu bumbu kuning 1pcs | B21: tahu bumbu kuning 1pcs | C21: susu | D21: susu | E21: dimsum ayam 2 | F21: dimsum ayam 2 | G21: susu | H21: susu | I21: ayam goreng 1 pcs | J21: ayam goreng 1 pcs | K21: sari kacang hijau 1 | L21: sari kacang hijau 1
A22: markisa | B22: markisa | C22: naga | D22: naga | E22: sari kacang hijau 1 | F22: sari kacang hijau 1 | G22: jeruk manis | H22: jeruk manis | I22: anggur 4 | J22: anggur 4 | K22: telur puyuh 30gr | L22: telur puyuh 30gr
B23: Kurma 35grm | D23: kurma | F23: Kurma 35grm | H23: kurma 3 | J23: Kurma 35gr | L23: Kurma 35gr
I25: roti | J25: roti
I26: ayam | J26: ayam
I27: telur | J27: telur
I28: sari kacang hijau | J28: sari kacang hijau
I29: apel | J29: apel
J30: kurma
A31: MENU B3 | F31: PENERIMA MANFAAT
A32: Selasa 10/03/26 | C32: Kamis 12/03/26 | F32: PAUD, TK, SD 1 - 3 | G32: 1043
A33: BALITA 9 | B33: IBU 10 | C33: BALITA | D33: IBU | F33: SD 4 - 6, SMP, SMA | G33: =1070+253+1 -> 1324
A34: Goguma bread 2 | B34: Goguma bread 2 | C34: Goguma Bread 2 | D34: Goguma Bread 2 | F34: BALITA | G34: 204
A35: ayam bumbu kuning 2 | B35: ayam bumbu kuning 2 | C35: Telur ayam rebus 2 | D35: Telur ayam rebus 2 | F35: IBU | G35: =297+16+1 -> 314
A36: sari kacang hijau 100ml 1pcs | B36: sari kacang hijau 100ml 1pcs | C36: susu kecil 2 | D36: susu kecil 2 | F36: B3 | G36: =G35+G34 -> 518
A37: Jeruk 1 | B37: Jeruk 1 | C37: markisa 1 | D37: markisa 1 | F37: PORSI KECIL | G37: =G34+G32 -> 1247
A38: markisa 1 | B38: markisa 1 | C38: Jeruk 1 | D38: Jeruk 1 | F38: PORSI BESAR | G38: =G33+G35 -> 1638
A39: Kelengkeng 5 | B39: Kurma 10 | C39: lengkeng | D39: Kurma 10 | F39: TOTAL | G39: =SUM(G32:G35) -> 2885
A41: tahu 2 | B41: tahu 2 | C41: tahu 2 | D41: tahu 2
C42: tempe 1 | D42: tempe 1

Sheet 9 MARET
A1: 1 | C1: 9-11 MARET | E1: RAPEL 3 HARI
L2: PENERIMA MANFAAT
A3: MENU | C3: jangan lupa di list paliing bawah diketik kebutuhan wadah ya, plastik mika untuk bahan makanan apa aja | L3: PAUD, TK, SD 1 - 3 | M3: 1043 | N3: =M3*8000 -> 8344000
A4: KECIL | B4: BESAR | L4: SD 4 - 6, SMP, SMA | M4: =1070+253+1 -> 1324 | N4: =M4*10000 -> 13240000
A5: ayam kuning 1 potong | B5: ayam kuning 1 potong | L5: BALITA | M5: 204 | N5: =N3+N4 -> 21584000
A6: tahu bumbu kuning 1pcs | B6: tahu bumbu kuning 1pcs | L6: IBU | M6: =297+16+1 -> 314
A7: markisa | B7: markisa | L7: B3 | M7: =M6+M5 -> 518
B8: Kurma 35grm | L8: PORSI KECIL | M8: =M5+M3 -> 1247
L9: PORSI BESAR | M9: =M4+M6 -> 1638
L10: TOTAL | M10: =SUM(M3:M6) -> 2885
A13: Karbohidrat | C13: Berat Kotor (Gram) | D13: Murid | E13: Total (gram) | F13: Buffer 3% (Gram) | G13: Dalam (Kg) | H13: Satuan | I13: Harga/Satuan | J13: Total
C14: 0 | D14: 0 | E14: =C14*D14 -> 0 | F14: =((E16+E16*3%)) -> 0 | G14: =F14/1000 -> 0 | H14: Kg
E15: =C15*D15 -> 0
A16: Total | E16: =E14+E15 -> 0
A17: Protein Hewani
A18: Porsi Kecil | B18: Ayam 1kg 12 | C18: =1000/12 -> 83.333333 | D18: 1043 | E18: =C18*D18 -> 86916.667 | F18: =(E18+(E18*4%)) -> 90393.333 | G18: =+F18/1000 -> 90.393333 | H18: Kg | I18: 40000 | J18: =G18*I18 -> 3615733.3 | K18: =E18/1000 -> 86.916667
A19: Porsi Besar | B19: Ayam 1kg 10 | C19: =1000/10 -> 100 | D19: 1324 | E19: =C19*D19 -> 132400 | F19: =(E19+(E19*4%)) -> 137696 | G19: =+F19/1000 -> 137.696 | H19: Kg | I19: 40000 | J19: =G19*I19 -> 5507840 | K19: =E19/1000 -> 132.4
A20: Protein Nabati | J20: =G20*I20 -> 0 | K20: =E20/1000 -> 0
B21: Tahu | C21: 1 | D21: =M3+M4 -> 2367 | E21: =C21*D21 -> 2367 | F21: =(E21+(E21*4%)) -> 2461.68 | G21: =+F21 -> 2461.68 | H21: Pcs | I21: 650 | J21: =G21*I21 -> 1600092 | K21: =E21/1000 -> 2.367
J22: =G22*I22 -> 0 | K22: =E22/1000 -> 0
A23: Sayur | J23: =G23*I23 -> 0 | K23: =E23/1000 -> 0
A24: Buah | J24: =G24*I24 -> 0 | K24: =E24/1000 -> 0
B25: Markisa | C25: 1 | D25: =M3+M4 -> 2367 | E25: =C25*D25 -> 2367 | F25: =(E25+(E25*3%)) -> 2438.01 | G25: =+F25 -> 2438.01 | H25: pcs | I25: 2500 | J25: =G25*I25 -> 6095025 | K25: =E25/1000 -> 2.367
B26: Kurma 35grm | C26: 35 | D26: 1324 | E26: =C26*D26 -> 46340 | F26: =(E26+(E26*3%)) -> 47730.2 | G26: =+F26/1000 -> 47.7302 | H26: Kg | I26: 40000 | J26: =G26*I26 -> 1909208 | K26: =E26/1000 -> 46.34
A27: Lainnya | K27: =E27/1000 -> 0
B28: kunyit | C28: 1 | D28: 2367 | E28: =C28*D28 -> 2367 | F28: =(E28+(E28*3%)) -> 2438.01 | G28: =+F28/1000 -> 2.43801 | H28: Kg | I28: 15000 | J28: =K28*I28 -> 35505 | K28: =E28/1000 -> 2.367
B29: jahe | C29: 0.5 | D29: 2367 | E29: =C29*D29 -> 1183.5 | F29: =(E29+(E29*3%)) -> 1219.005 | G29: =+F29/1000 -> 1.219005 | H29: Kg | I29: 27000 | J29: =K29*I29 -> 31954.5 | K29: =E29/1000 -> 1.1835
B30: kemiri | C30: 0.5 | D30: 2367 | E30: =C30*D30 -> 1183.5 | F30: =(E30+(E30*3%)) -> 1219.005 | G30: =+F30/1000 -> 1.219005 | H30: Kg | I30: 50000 | J30: =K30*I30 -> 59175 | K30: =E30/1000 -> 1.1835
B31: bawang merah kupas | C31: 1 | D31: 2367 | E31: =C31*D31 -> 2367 | F31: =(E31+(E31*3%)) -> 2438.01 | G31: =+F31/1000 -> 2.43801 | H31: Kg | I31: 45000 | J31: =K31*I31 -> 106515 | K31: =E31/1000 -> 2.367
B32: bawang putih kupas | C32: 1 | D32: 2367 | E32: =C32*D32 -> 2367 | F32: =(E32+(E32*3%)) -> 2438.01 | G32: =+F32/1000 -> 2.43801 | H32: Kg | I32: 43000 | J32: =K32*I32 -> 101781 | K32: =E32/1000 -> 2.367
B33: ketumbar bubuk | C33: 0.7 | D33: 2367 | E33: =C33*D33 -> 1656.9 | F33: =(E33+(E33*3%)) -> 1706.607 | G33: =+F33/1000 -> 1.706607 | H33: Kg | I33: 35000 | J33: =K33*I33 -> 57991.5 | K33: =E33/1000 -> 1.6569
B34: garam | C34: 3 | D34: 2367 | E34: =C34*D34 -> 7101 | F34: =(E34+(E34*3%)) -> 7314.03 | G34: =+F34/1000 -> 7.31403 | H34: Kg | I34: 13000 | J34: =K34*I34 -> 92313 | K34: =E34/1000 -> 7.101
B35: knor ayam | C35: 1 | D35: 2367 | E35: =C35*D35 -> 2367 | F35: =(E35+(E35*3%)) -> 2438.01 | G35: =+F35/1000 -> 2.43801 | H35: Kg | I35: 102000 | J35: =K35*I35 -> 241434 | K35: =E35/1000 -> 2.367
B36: gula pasir | C36: 3 | D36: 2367 | E36: =C36*D36 -> 7101 | F36: =(E36+(E36*3%)) -> 7314.03 | G36: =+F36/1000 -> 7.31403 | H36: Kg | I36: 19000 | J36: =K36*I36 -> 134919 | K36: =E36/1000 -> 7.101
B37: miwon | C37: 1 | D37: 2367 | E37: =C37*D37 -> 2367 | F37: =(E37+(E37*3%)) -> 2438.01 | G37: =+F37/1000 -> 2.43801 | H37: Kg | I37: 53000 | J37: =K37*I37 -> 125451 | K37: =E37/1000 -> 2.367
B38: minyak goreng | C38: 15 | D38: 2367 | E38: =C38*D38 -> 35505 | F38: =(E38+(E38*3%)) -> 36570.15 | G38: =+F38/1000 -> 36.57015 | H38: Liter | I38: 19500 | J38: =K38*I38 -> 692347.5 | K38: =E38/1000 -> 35.505
B39: daun salam | C39: 0.5 | D39: 2367 | E39: =C39*D39 -> 1183.5 | F39: =(E39+(E39*3%)) -> 1219.005 | G39: =+F39/1000 -> 1.219005 | H39: Kg | I39: 16000 | J39: =K39*I39 -> 18936 | K39: =E39/1000 -> 1.1835
B40: Sereh | C40: 0.5 | D40: 2367 | E40: =C40*D40 -> 1183.5 | F40: =(E40+(E40*3%)) -> 1219.005 | G40: =+F40/1000 -> 1.219005 | H40: Kg | I40: 17000 | J40: =K40*I40 -> 20119.5 | K40: =E40/1000 -> 1.1835
B41: sausa tiram panda | C41: 0.5 | D41: 2367 | E41: =C41*D41 -> 1183.5 | F41: =(E41+(E41*3%)) -> 1219.005 | G41: =F41/1000 -> 1.219005 | H41: Liter | I41: 59000 | J41: =K41*I41 -> 69826.5 | K41: =E41/1000 -> 1.1835
B42: Plastik kurma | C42: 1 | D42: 1324 | E42: =C42*D42 -> 1324 | F42: =(E42+(E42*3%)) -> 1363.72 | G42: =F42/1000 -> 1.36372 | H42: Pcs | J42: =SUM(J18:J41) -> 20516167
...

Sheet 10 MARET 
A1: 1
A3: MENU | L3: PENERIMA MANFAAT
A4: KECIL | B4: BESAR | L4: PAUD, TK, SD 1 - 3 | M4: 1043
A5: Roti abon | B5: roti abon | L5: SD 4 - 6, SMP, SMA | M5: =1070+253+1 -> 1324
A6: susu | B6: susu | L6: BALITA | M6: 204
A7: naga | B7: naga | L7: IBU | M7: =297+16+1 -> 314
B8: kurma | L8: B3 | M8: =M7+M6 -> 518
L9: PORSI KECIL | M9: =M6+M4 -> 1247
L10: PORSI BESAR | M10: =M5+M7 -> 1638
L11: TOTAL | M11: =SUM(M4:M7) -> 2885
A15: karbohidrat | C15: Berat Kotor (Gram) | D15: Murid | E15: Total (gram) | F15: Buffer 3% (Gram) | G15: Dalam (Kg) | H15: Satuan | I15: Harga/Satuan | J15: Total
B16: roti abon | C16: 1 | D16: 2367 | E16: =C16*D16 -> 2367 | F16: =((E16+E16*3%)) -> 2438.01 | G16: =F16 -> 2438.01 | H16: pcs | I16: 2100 | J16: =G16*I16 -> 5119821 | K16: =E16/1000 -> 2.367
J17: =G17*I17 -> 0 | K17: =E17/1000 -> 0
A18: Protein Hewani | J18: =G18*I18 -> 0 | K18: =E18/1000 -> 0
A19: Porsi Kecil | B19: susu 115ml | C19: 1 | D19: 2367 | E19: =C19*D19 -> 2367 | F19: =(E19+(E19*3%)) -> 2438.01 | G19: =+F19 -> 2438.01 | H19: Kg | I19: 3500 | J19: =G19*I19 -> 8533035 | K19: =E19/1000 -> 2.367
A20: Porsi Besar | C20: 0 | D20: =1070+253+1 -> 1324 | E20: =C20*D20 -> 0 | F20: =(E20+(E20*4%)) -> 0 | G20: =+F20/1000 -> 0 | H20: Kg | J20: =G20*I20 -> 0 | K20: =E20/1000 -> 0
A21: Protein Nabati | J21: =G21*I21 -> 0 | K21: =E21/1000 -> 0
C22: 1 | D22: 2367 | E22: =C22*D22 -> 2367 | F22: =(E22+(E22*3%)) -> 2438.01 | G22: =F22 -> 2438.01 | H22: pcs | J22: =G22*I22 -> 0 | K22: =E22/1000 -> 2.367
A23: Sayur | J23: =G23*I23 -> 0 | K23: =E23/1000 -> 0
A24: Buah | J24: =G24*I24 -> 0 | K24: =E24/1000 -> 0
A25: porsi besar | B25: kurma 35gr | C25: 35 | D25: 1324 | E25: =C25*D25 -> 46340 | F25: =(E25+(E25*3%)) -> 47730.2 | G25: =F25/1000 -> 47.7302 | H25: kg | I25: 40000 | J25: =G25*I25 -> 1909208 | K25: =E25/1000 -> 46.34
B26: naga | C26: 1 | D26: 2367 | E26: =C26*D26 -> 2367 | F26: =(E26+(E26*3%)) -> 2438.01 | G26: =+F26 -> 2438.01 | H26: pcs | I26: 4500 | J26: =G26*I26 -> 10971045 | K26: =E26/1000 -> 2.367
J27: =SUM(J16:J26) -> 26533109 | K27: =E27/1000 -> 0
B28: plastik kurma | C28: 1 | D28: 1324 | E28: =C28*D28 -> 1324 | F28: =(E28+(E28*3%)) -> 1363.72 | G28: =F28 -> 1363.72 | H28: Pcs
A31: Kandungan gizi TK dan SD 1-3
A32: Bahan Makanan | B32: BDD % | C32: Berat Kotor | D32: Berat Bersih | E32: Faktor Konversi | F32: Penyajian (gr) | G32: URT | H32: Energi | I32: Protein | J32: Lemak | K32: Karbohidrat | L32: Serat
A33: Roti abon | B33: 100 | C33: 115 | D33: =B33%*C33 -> 115 | E33: 1 | F33: =D33/E33 -> 115 | G33: 1 kotak kecil | H33: 60 | I33: 3 | J33: 3 | K33: 6 | L33: 0
A34: susu 115ml | B34: 100 | C34: 115 | D34: =B34%*C34 -> 115 | E34: 1 | F34: =D34/E34 -> 115 | G34: 1 kotak kecil | H34: 70 | I34: 3 | J34: 3.5 | K34: 6 | L34: 0
A35: naga | B35: 66.5 | C35: 250 | D35: =B35%*C35 -> 166.25 | E35: 1 | F35: =D35/E35 -> 166.25 | G35: 1 buah sedang | H35: 71 | I35: 1.7 | J35: 3.1 | K35: 9.1 | L35: 3.2
A36: TOTAL | H36: =SUM(H33:H35) -> 201 | I36: =SUM(I33:I35) -> 7.7 | J36: =SUM(J33:J35) -> 9.6 | K36: =SUM(K33:K35) -> 21.1 | L36: =SUM(L33:L35) -> 3.2
A37: 20 % KEBUTUHAN HARIAN | H37: 330 | I37: 8 | J37: 11 | K37: 50 | L37: 4
A38: % KECUKUPAN GIZI | H38: =(H36/H37)*100 -> 60.909091 | I38: =(I36/I37)*100 -> 96.25 | J38: =(J36/J37)*100 -> 87.272727 | K38: =(K36/K37)*100 -> 42.2 | L38: =(L36/L37)*100 -> 80
A41: Kandungan gizi SD 4-6 DAN SMP - SMA
A42: Bahan Makanan | B42: BDD % | C42: Berat Kotor | D42: Berat Bersih | E42: Faktor Konversi | F42: Penyajian (gr) | G42: URT | H42: Energi | I42: Protein | J42: Lemak | K42: Karbohidrat | L42: Serat
A43: Roti abon | B43: 100 | C43: 115 | D43: =B43%*C43 -> 115 | E43: 1 | F43: =D43/E43 -> 115 | G43: 1 kotak kecil | H43: 60 | I43: 3 | J43: 3 | K43: 6 | L43: 0
A44: susu 115ml | B44: 100 | C44: 115 | D44: =B44%*C44 -> 115 | E44: 1 | F44: =D44/E44 -> 115 | G44: 1 kotak kecil | H44: 70 | I44: 3 | J44: 3.5 | K44: 6 | L44: 0
A45: naga | B45: 66.5 | C45: 250 | D45: =B45%*C45 -> 166.25 | E45: 1 | F45: =D45/E45 -> 166.25 | G45: 1 buah sedang | H45: 71 | I45: 1.7 | J45: 3.1 | K45: 9.1 | L45: 3.2
A46: Kurma | B46: 79 | C46: 35 | D46: =B46%*C46 -> 27.65 | E46: 1 | F46: =D46/E46 -> 27.65 | G46: 3 bijji | H46: 78.1 | I46: 0.8 | J46: 0.1 | K46: 20.6 | L46: 1
A47: TOTAL | H47: =SUM(H43:H46) -> 279.1 | I47: =SUM(I43:I46) -> 8.5 | J47: =SUM(J43:J46) -> 9.7 | K47: =SUM(K43:K46) -> 41.7 | L47: =SUM(L43:L46) -> 4.2
A48: 30 % KEBUTUHAN HARIAN | H48: 668 | I48: 20.3 | J48: 22.5 | K48: 97.5 | L48: 10
...

Sheet B3 10 MARET
A1: 1
A3: MENU | L3: PENERIMA MANFAAT
A4: KECIL | B4: BESAR | L4: PAUD, TK, SD 1 - 3 | M4: 1043
A5: Goguma bread 2 | B5: Goguma bread 2 | L5: SD 4 - 6, SMP, SMA | M5: =1070+253+1 -> 1324
A6: ayam bumbu kuning 2 | B6: ayam bumbu kuning 2 | L6: BALITA | M6: 204 | N6: =M6*8000 -> 1632000
A7: sari kacang hijau 100ml 1pcs | B7: sari kacang hijau 100ml 1pcs | L7: IBU | M7: =297+16+1 -> 314 | N7: =M7*10000 -> 3140000
A8: Jeruk 1 | B8: Jeruk 1 | L8: B3 | M8: =M7+M6 -> 518 | N8: =N6+N7 -> 4772000 | O8: =N8*3 -> 14316000
A9: markisa 1 | B9: markisa 1 | L9: PORSI KECIL | M9: =M6+M4 -> 1247
A10: Kelengkeng 50 | B10: Kurma 10 | L10: PORSI BESAR | M10: =M5+M7 -> 1638
L11: TOTAL | M11: =SUM(M4:M7) -> 2885
A15: karbohidrat | C15: Berat Kotor (Gram) | D15: Murid | E15: Total (gram) | F15: Buffer 3% (Gram) | G15: Dalam (Kg) | H15: Satuan | I15: Harga/Satuan | J15: Total
A16: Goguma bread 2 | B16: Roti Lembaran | C16: 2 | D16: 518 | E16: =C16*D16 -> 1036 | F16: =((E16+E16*3%)) -> 1067.08 | G16: =F16 -> 1067.08 | H16: pcs | I16: 1000 | J16: =G16*I16 -> 1067080 | K16: =E16/1000 -> 1.036
B17: Ubi Ungu | C17: 50 | D17: 518 | E17: =C17*D17 -> 25900 | F17: =((E17+E17*3%)) -> 26677 | G17: =+F17/1000 -> 26.677 | H17: Kg | I17: 13000 | J17: =G17*I17 -> 346801 | K17: =E17/1000 -> 25.9
A18: Protein Hewani | J18: =G18*I18 -> 0 | K18: =E18/1000 -> 0
A19: Porsi Kecil | B19: Ayam 1kg 12 | C19: =1000/12*2 -> 166.66667 | D19: 204 | E19: =C19*D19 -> 34000 | F19: =(E19+(E19*4%)) -> 35360 | G19: =+F19/1000 -> 35.36 | H19: Kg | I19: 40000 | J19: =G19*I19 -> 1414400 | K19: =E19/1000 -> 34
A20: Porsi Besar | B20: Ayam 1kg 10 | C20: =1000/10*2 -> 200 | D20: 314 | E20: =C20*D20 -> 62800 | F20: =(E20+(E20*4%)) -> 65312 | G20: =+F20/1000 -> 65.312 | H20: Kg | I20: 40000 | J20: =G20*I20 -> 2612480 | K20: =E20/1000 -> 62.8
A21: Protein Nabati | J21: =G21*I21 -> 0 | K21: =E21/1000 -> 0
B22: sari kacang hijau 100ml 1pcs | C22: 1 | D22: 518 | E22: =C22*D22 -> 518 | F22: =(E22+(E22*3%)) -> 533.54 | G22: =F22 -> 533.54 | H22: pcs | I22: 2300 | J22: =G22*I22 -> 1227142 | K22: =E22/1000 -> 0.518
A23: Sayur | J23: =G23*I23 -> 0 | K23: =E23/1000 -> 0
A24: Buah | J24: =G24*I24 -> 0 | K24: =E24/1000 -> 0
B25: Jeruk | C25: 1 | D25: 518 | E25: =C25*D25 -> 518 | F25: =(E25+(E25*3%)) -> 533.54 | G25: =F25 -> 533.54 | H25: pcs | I25: 2300 | J25: =G25*I25 -> 1227142 | K25: =E25/1000 -> 0.518
B26: Markisa | C26: 1 | D26: 518 | E26: =C26*D26 -> 518 | F26: =(E26+(E26*3%)) -> 533.54 | G26: =F26 -> 533.54 | H26: pcs | I26: 2500 | J26: =G26*I26 -> 1333850 | K26: =E26/1000 -> 0.518
B27: Kelengkeng | C27: 40 | D27: 518 | E27: =C27*D27 -> 20720 | F27: =(E27+(E27*3%)) -> 21341.6 | G27: =+F27/1000 -> 21.3416 | H27: pcs | I27: 50000 | J27: =G27*I27 -> 1067080 | K27: =E27/1000 -> 20.72
B28: kurma 10 | C28: 110 | D28: 314 | E28: =C28*D28 -> 34540 | F28: =(E28+(E28*3%)) -> 35576.2 | G28: =+F28/1000 -> 35.5762 | H28: Kg | I28: 40000 | J28: =G28*I28 -> 1423048 | K28: =E28/1000 -> 34.54
A29: Lainnya | K29: =E29/1000 -> 0
B30: Susu Kental Manis | C30: 30 | D30: 518 | E30: =C30*D30 -> 15540 | F30: =(E30+(E30*3%)) -> 16006.2 | G30: =F30/1000 -> 16.0062 | H30: liter | I30: 26000 | J30: =K30*I30 -> 404040 | K30: =E30/1000 -> 15.54
B31: Telur | C31: =1000/15/10 -> 6.6666667 | D31: 518 | E31: =C31*D31 -> 3453.3333 | F31: =(E31+(E31*3%)) -> 3556.9333 | G31: =F31/1000 -> 3.5569333 | H31: Kg | I31: 32000 | J31: =K31*I31 -> 110506.67 | K31: =E31/1000 -> 3.4533333
B32: Tepung Panir kuning | C32: 50 | D32: 518 | E32: =C32*D32 -> 25900 | F32: =(E32+(E32*3%)) -> 26677 | G32: =+F32/1000 -> 26.677 | H32: Kg | I32: 18000 | J32: =K32*I32 -> 466200 | K32: =E32/1000 -> 25.9
B33: kunyit utuh | C33: 2 | D33: 518 | E33: =C33*D33 -> 1036 | F33: =(E33+(E33*3%)) -> 1067.08 | G33: =+F33/1000 -> 1.06708 | H33: Kg | I33: 15000 | J33: =K33*I33 -> 15540 | K33: =E33/1000 -> 1.036
B34: jahe utuh | C34: 2 | D34: 518 | E34: =C34*D34 -> 1036 | F34: =(E34+(E34*3%)) -> 1067.08 | G34: =+F34/1000 -> 1.06708 | H34: Kg | I34: 27000 | J34: =K34*I34 -> 27972 | K34: =E34/1000 -> 1.036
B35: kemiri | C35: 1 | D35: 518 | E35: =C35*D35 -> 518 | F35: =(E35+(E35*3%)) -> 533.54 | G35: =+F35/1000 -> 0.53354 | H35: Kg | I35: 50000 | J35: =K35*I35 -> 25900 | K35: =E35/1000 -> 0.518
B36: bawang merah kupas | C36: 2 | D36: 518 | E36: =C36*D36 -> 1036 | F36: =(E36+(E36*3%)) -> 1067.08 | G36: =+F36/1000 -> 1.06708 | H36: Kg | I36: 45000 | J36: =K36*I36 -> 46620 | K36: =E36/1000 -> 1.036
B37: bawang putih kupas | C37: 2 | D37: 518 | E37: =C37*D37 -> 1036 | F37: =(E37+(E37*3%)) -> 1067.08 | G37: =+F37/1000 -> 1.06708 | H37: Kg | I37: 43000 | J37: =K37*I37 -> 44548 | K37: =E37/1000 -> 1.036
B38: ketumbar bubuk | C38: 1 | D38: 518 | E38: =C38*D38 -> 518 | F38: =(E38+(E38*3%)) -> 533.54 | G38: =+F38/1000 -> 0.53354 | H38: Kg | I38: 35000 | J38: =K38*I38 -> 18130 | K38: =E38/1000 -> 0.518
B39: garam | C39: 4 | D39: 518 | E39: =C39*D39 -> 2072 | F39: =(E39+(E39*3%)) -> 2134.16 | G39: =+F39/1000 -> 2.13416 | H39: Kg | I39: 13000 | J39: =K39*I39 -> 26936 | K39: =E39/1000 -> 2.072
B40: knor ayam | C40: 2 | D40: 518 | E40: =C40*D40 -> 1036 | F40: =(E40+(E40*3%)) -> 1067.08 | G40: =+F40/1000 -> 1.06708 | H40: Kg | I40: 102000 | J40: =K40*I40 -> 105672 | K40: =E40/1000 -> 1.036
B41: gula pasir | C41: 4 | D41: 518 | E41: =C41*D41 -> 2072 | F41: =(E41+(E41*3%)) -> 2134.16 | G41: =+F41/1000 -> 2.13416 | H41: Kg | I41: 19000 | J41: =K41*I41 -> 39368 | K41: =E41/1000 -> 2.072
B42: miwon | C42: 2 | D42: 518 | E42: =C42*D42 -> 1036 | F42: =(E42+(E42*3%)) -> 1067.08 | G42: =+F42/1000 -> 1.06708 | H42: Kg | I42: 53000 | J42: =K42*I42 -> 54908 | K42: =E42/1000 -> 1.036
B43: minyak goreng | C43: 15 | D43: 518 | E43: =C43*D43 -> 7770 | F43: =(E43+(E43*3%)) -> 8003.1 | G43: =+F43/1000 -> 8.0031 | H43: Liter | I43: 19500 | J43: =K43*I43 -> 151515 | K43: =E43/1000 -> 7.77
... B45: Sereh | C45: 1 | D45: 518 | E45: =C45*D45 -> 518 | F45: =(E45+(E45*3%)) -> 533.54 | G45: =+F45/1000 -> 0.53354 | H45: Kg | I45: 17000 | J45: =K45*I45 -> 8806 | K45: =E45/1000 -> 0.518
...

Sheet 11 MARET
A3: MENU
A4: KECIL | B4: BESAR | L4: PENERIMA MANFAAT
A5: roti pizza | B5: roti pizza | L5: PAUD, TK, SD 1 - 3 | M5: 1043
A6: dimsum ayam 2 | B6: dimsum ayam 2 | L6: SD 4 - 6, SMP, SMA | M6: =1070+253+1 -> 1324
A7: sari kacang hijau 1 | B7: sari kacang hijau 1 | L7: BALITA | M7: 204
B8: Kurma 35grm | L8: IBU | M8: =297+16+1 -> 314
L9: B3 | M9: =M8+M7 -> 518
L10: PORSI KECIL | M10: =M7+M5 -> 1247
L11: PORSI BESAR | M11: =M6+M8 -> 1638
L12: TOTAL | M12: =SUM(M5:M8) -> 2885
A14: Karbohidrat | C14: Berat Kotor (Gram) | D14: Murid | E14: Total (gram) | F14: Buffer 3% (Gram) | G14: Dalam (Kg) | H14: Satuan | I14: Harga/Satuan | J14: Total
B15: Roti Pizza | C15: 1 | D15: 2367 | E15: =C15*D15 -> 2367 | F15: =(E15+(E15*3%)) -> 2438.01 | G15: =+F15 -> 2438.01 | H15: Pcs | I15: 2200 | J15: =G15*I15 -> 5363622 | K15: =E15/1000 -> 2.367
A16: Protein Hewani | J16: =G16*I16 -> 0 | K16: =E16/1000 -> 0
A17: dimsum | B17: Ayam giling MDM | C17: 25 | D17: 2367 | E17: =C17*D17 -> 59175 | F17: =(E17+(E17*3%)) -> 60950.25 | G17: =+F17/1000 -> 60.95025 | H17: Kg | I17: 29500 | J17: =G17*I17 -> 1798032.4 | K17: =E17/1000 -> 59.175
A18: Protein Nabati | J18: =G18*I18 -> 0 | K18: =E18/1000 -> 0
B19: Sari kacang hijau 100ml | C19: 1 | D19: 2367 | E19: =C19*D19 -> 2367 | F19: =(E19+(E19*3%)) -> 2438.01 | G19: =F19 -> 2438.01 | H19: pcs | I19: 2300 | J19: =G19*I19 -> 5607423 | K19: =E19/1000 -> 2.367
A20: Sayur | J20: =G20*I20 -> 0 | K20: =E20/1000 -> 0
B21: Wortel serut | C21: =5*4 -> 20 | D21: 2367 | E21: =C21*D21 -> 47340 | F21: =(E21+(E21*3%)) -> 48760.2 | G21: =+F21/1000 -> 48.7602 | H21: Kg | I21: 25000 | J21: =G21*I21 -> 1219005 | K21: =E21/1000 -> 47.34
A22: Buah | J22: =G22*I22 -> 0 | K22: =E22/1000 -> 0
C23: 0 | D23: 1043 | E23: =C23*D23 -> 0 | F23: =(E23+(E23*3%)) -> 0 | G23: =+F23/1000 -> 0 | H23: Pcs | I23: 50000 | J23: =G23*I23 -> 0 | K23: =E23/1000 -> 0
B24: Kurma 35gr | C24: 35 | D24: 1324 | E24: =C24*D24 -> 46340 | F24: =(E24+(E24*3%)) -> 47730.2 | G24: =+F24/1000 -> 47.7302 | H24: Kg | I24: 40000 | J24: =G24*I24 -> 1909208 | K24: =E24/1000 -> 46.34
A25: Lainnya | K25: =E25/1000 -> 0
B26: daun bawang | C26: 3 | D26: 2367 | E26: =C26*D26 -> 7101 | F26: =(E26+(E26*3%)) -> 7314.03 | G26: =F26/1000 -> 7.31403 | H26: kg | I26: 14000 | J26: =K26*I26 -> 99414 | K26: =E26/1000 -> 7.101
B27: Telur | C27: 6 | D27: 2367 | E27: =C27*D27 -> 14202 | F27: =(E27+(E27*3%)) -> 14628.06 | G27: =F27/1000 -> 14.62806 | H27: Kg | I27: 32000 | J27: =K27*I27 -> 454464 | K27: =E27/1000 -> 14.202
B28: Tepung tapioka | C28: 10 | D28: 2367 | E28: =C28*D28 -> 23670 | F28: =(E28+(E28*3%)) -> 24380.1 | G28: =+F28/1000 -> 24.3801 | H28: Kg | I28: 16000 | J28: =K28*I28 -> 378720 | K28: =E28/1000 -> 23.67
B29: Jahe | C29: 0.7 | D29: 2367 | E29: =C29*D29 -> 1656.9 | F29: =(E29+(E29*3%)) -> 1706.607 | G29: =+F29/1000 -> 1.706607 | H29: Kg | I29: 27000 | J29: =K29*I29 -> 44736.3 | K29: =E29/1000 -> 1.6569
B30: Minyak Wijen | C30: 0.7 | D30: 2367 | E30: =C30*D30 -> 1656.9 | F30: =(E30+(E30*3%)) -> 1706.607 | G30: =+F30/1000 -> 1.706607 | H30: Kg | I30: 49000 | J30: =K30*I30 -> 81188.1 | K30: =E30/1000 -> 1.6569
B31: Kecap asin | C31: 0.5 | D31: 2367 | E31: =C31*D31 -> 1183.5 | F31: =(E31+(E31*3%)) -> 1219.005 | G31: =+F31/1000 -> 1.219005 | H31: Kg | I31: 49000 | J31: =K31*I31 -> 57991.5 | K31: =E31/1000 -> 1.1835
B32: Saos Tiram | C32: 0.7 | D32: 2367 | E32: =C32*D32 -> 1656.9 | F32: =(E32+(E32*3%)) -> 1706.607 | G32: =+F32/1000 -> 1.706607 | H32: Kg | I32: 59000 | J32: =K32*I32 -> 97757.1 | K32: =E32/1000 -> 1.6569
B33: Tepung terigu | C33: 10 | D33: 2367 | E33: =C33*D33 -> 23670 | F33: =(E33+(E33*3%)) -> 24380.1 | G33: =+F33/1000 -> 24.3801 | H33: Kg | I33: 13000 | J33: =K33*I33 -> 307710 | K33: =E33/1000 -> 23.67
B34: gula Pasir | C34: 3 | D34: 2367 | E34: =C34*D34 -> 7101 | F34: =(E34+(E34*3%)) -> 7314.03 | G34: =+F34/1000 -> 7.31403 | H34: Kg | I34: 19000 | J34: =K34*I34 -> 134919 | K34: =E34/1000 -> 7.101
B35: minyak goreng | C35: 10 | D35: 2367 | E35: =C35*D35 -> 23670 | F35: =(E35+(E35*3%)) -> 24380.1 | G35: =F35/1000 -> 24.3801 | H35: Litter | I35: 19500 | J35: =K35*I35 -> 461565 | K35: =E35/1000 -> 23.67
B36: Kulit pangsit bulat | C36: 2 | D36: 2367 | E36: =C36*D36 -> 4734 | F36: =(E36+(E36*3%)) -> 4876.02 | G36: =F36 -> 4876.02 | H36: pcs | I36: 450 | J36: =G36*I36 -> 2194209 | K36: =E36/1000 -> 4.734
B37: bawang merah kupas | C37: 1 | D37: 2367 | E37: =C37*D37 -> 2367 | F37: =(E37+(E37*3%)) -> 2438.01 | G37: =F37/1000 -> 2.43801 | H37: Kg | I37: 45000 | J37: =K37*I37 -> 106515 | K37: =E37/1000 -> 2.367
B38: bawang putih kupas | C38: 1.2 | D38: 2367 | E38: =C38*D38 -> 2840.4 | F38: =(E38+(E38*3%)) -> 2925.612 | G38: =F38/1000 -> 2.925612 | H38: Kg | I38: 43000 | J38: =K38*I38 -> 122137.2 | K38: =E38/1000 -> 2.8404
B39: garam | C39: 1.5 | D39: 2367 | E39: =C39*D39 -> 3550.5 | F39: =(E39+(E39*3%)) -> 3657.015 | G39: =F39/1000 -> 3.657015 | H39: Kg | I39: 13000 | J39: =K39*I39 -> 46156.5 | K39: =E39/1000 -> 3.5505
B40: knor ayam | C40: 1 | D40: 2367 | E40: =C40*D40 -> 2367 | F40: =(E40+(E40*3%)) -> 2438.01 | G40: =F40/1000 -> 2.43801 | H40: Kg | I40: 102000 | J40: =K40*I40 -> 241434 | K40: =E40/1000 -> 2.367
B41: miwon | C41: 0.5 | D41: 2367 | E41: =C41*D41 -> 1183.5 | F41: =(E41+(E41*3%)) -> 1219.005 | G41: =F41/1000 -> 1.219005 | H41: Kg | I41: 53000 | J41: =K41*I41 -> 62725.5 | K41: =E41/1000 -> 1.1835
B42: lada | C42: 1 | D42: 2367 | E42: =C42*D42 -> 2367 | F42: =(E42+(E42*3%)) -> 2438.01 | G42: =F42/1000 -> 2.43801 | H42: Kg | I42: 60000 | J42: =K42*I42 -> 142020 | K42: =E42/1000 -> 2.367
B43: Mika wadah dimsum | C43: 1 | D43: 2367 | E43: =C43*D43 -> 2367 | F43: =(E43+(E43*3%)) -> 2438.01 | G43: =F43 -> 2438.01 | H43: Pcs | J43: =SUM(J15:J42) -> 20930953
...

Sheet 12 MARET 
A3: MENU
A4: KECIL | B4: BESAR
A5: Telur ayam rebus 1 | B5: Telur ayam rebus 1 | L5: PENERIMA MANFAAT
A6: susu 115ml | B6: susu 115ml | L6: PAUD, TK, SD 1 - 3 | M6: 1043
A7: jeruk manis | B7: jeruk manis | L7: SD 4 - 6, SMP, SMA | M7: =1070+253+1 -> 1324
B8: kurma 3 | L8: BALITA | M8: 204
L9: IBU | M9: =297+16+1 -> 314
L10: B3 | M10: =M9+M8 -> 518
L11: PORSI KECIL | M11: =M8+M6 -> 1247
L12: PORSI BESAR | M12: =M7+M9 -> 1638
L13: TOTAL | M13: =SUM(M6:M9) -> 2885
A15: Karbohidrat | C15: Berat Kotor (Gram) | D15: Murid | E15: Total (gram) | F15: Buffer 3% (Gram) | G15: Dalam (Kg) | H15: Satuan | I15: Harga/Satuan | J15: Total
A16: Protein Hewani | J16: =G16*I16 -> 0
B17: Telur Ayam | C17: =1000/15 -> 66.666667 | D17: 2367 | E17: =C17*D17 -> 157800 | F17: =(E17+(E17*4%)) -> 164112 | G17: =+F17/1000 -> 164.112 | H17: Kg | I17: 32000 | J17: =G17*I17 -> 5251584
B18: Susu 115 | C18: 1 | D18: 2367 | E18: =C18*D18 -> 2367 | F18: =(E18+(E18*4%)) -> 2461.68 | G18: =+F18 -> 2461.68 | H18: Pcs | I18: 3500 | J18: =G18*I18 -> 8615880
A19: Protein Nabati | J19: =G19*I19 -> 0
A20: Sayur | J20: =G20*I20 -> 0
A21: Buah | J21: =G21*I21 -> 0
B22: jeruk manis | C22: 1 | D22: 2367 | E22: =C22*D22 -> 2367 | F22: =(E22+(E22*3%)) -> 2438.01 | G22: =+F22 -> 2438.01 | H22: Pcs | I22: 2300 | J22: =G22*I22 -> 5607423
B23: kurma 3 butir | C23: 35 | D23: 1324 | E23: =C23*D23 -> 46340 | F23: =(E23+(E23*3%)) -> 47730.2 | G23: =+F23/1000 -> 47.7302 | H23: Kg | I23: 40000 | J23: =G23*I23 -> 1909208
A24: Lainnya
B25: Plastik goguma bread | C25: 1 | D25: 2367 | E25: =C25*D25 -> 2367 | F25: =(E25+(E25*3%)) -> 2438.01 | G25: =F25 -> 2438.01 | H25: Pcs | J25: =SUM(J16:J24) -> 21384095
B26: plastik kurma | C26: 1 | D26: 1324 | E26: =C26*D26 -> 1324 | F26: =(E26+(E26*3%)) -> 1363.72 | G26: =F26 -> 1363.72 | H26: pcs
B27: Mika wadah Utama | C27: 1 | D27: 2367 | E27: =C27*D27 -> 2367 | F27: =(E27+(E27*3%)) -> 2438.01 | G27: =F27 -> 2438.01 | H27: Pcs
A30: Kandungan gizi TK dan SD 1-3
A31: Bahan Makanan | B31: BDD % | C31: Berat Kotor | D31: Berat Bersih | E31: Faktor Konversi | F31: Penyajian (gr) | G31: URT | H31: Energi | I31: Protein | J31: Lemak | K31: Karbohidrat | L31: Serat
A32: Telur ayam | B32: 87 | C32: 66.7 | D32: =B32*C32% -> 58.029 | E32: 1 | F32: =D32/E32 -> 58.029 | G32: 1 butir | H32: 90 | I32: 7.3 | J32: 6.2 | K32: 0.6 | L32: 0
A33: susu 115ml | B33: 100 | C33: 115 | D33: =B33%*C33 -> 115 | E33: 1 | F33: =D33/E33 -> 115 | G33: 1 kotak kecil | H33: 70 | I33: 3 | J33: 3.5 | K33: 6 | L33: 0
A34: Jeruk 1 | B34: 72 | C34: 116 | D34: =B34%*C34 -> 83.52 | E34: 1 | F34: =D34/E34 -> 83.52 | G34: 1 bh besar | H34: 39.3 | I34: 0.8 | J34: 0.1 | K34: 9.9 | L34: 2
A35: TOTAL | H35: =SUM(H32:H34) -> 199.3 | I35: =SUM(I32:I34) -> 11.1 | J35: =SUM(J32:J34) -> 9.8 | K35: =SUM(K32:K34) -> 16.5 | L35: =SUM(L32:L34) -> 2
A36: 20 % KEBUTUHAN HARIAN | H36: 330 | I36: 8 | J36: 11 | K36: 50 | L36: 4
A37: % KECUKUPAN GIZI | H37: =(H35/H36)*100 -> 60.393939 | I37: =(I35/I36)*100 -> 138.75 | J37: =(J35/J36)*100 -> 89.090909 | K37: =(K35/K36)*100 -> 33 | L37: =(L35/L36)*100 -> 50
A40: Kandungan gizi SD 4-6 DAN SMP - SMA
A41: Bahan Makanan | B41: BDD % | C41: Berat Kotor | D41: Berat Bersih | E41: Faktor Konversi | F41: Penyajian (gr) | G41: URT | H41: Energi | I41: Protein | J41: Lemak | K41: Karbohidrat | L41: Serat
A42: Telur ayam | B42: 87 | C42: 66.7 | D42: =B42*C42% -> 58.029 | E42: 1 | F42: =D42/E42 -> 58.029 | G42: 1 butir | H42: 90 | I42: 7.3 | J42: 6.2 | K42: 0.6 | L42: 0
A43: susu 115ml | B43: 100 | C43: 115 | D43: =B43%*C43 -> 115 | E43: 1 | F43: =D43/E43 -> 115 | G43: 1 kotak kecil | H43: 70 | I43: 3 | J43: 3.5 | K43: 6 | L43: 0
A44: Jeruk 1 | B44: 72 | C44: 116 | D44: =B44%*C44 -> 83.52 | E44: 1 | F44: =D44/E44 -> 83.52 | G44: 1 bh besar | H44: 39.3 | I44: 0.8 | J44: 0.1 | K44: 9.9 | L44: 2
A45: Kurma | B45: 79 | C45: 35 | D45: =B45%*C45 -> 27.65 | E45: 1 | F45: =D45/E45 -> 27.65 | G45: 3 biji | H45: 52.2 | I45: 0.6 | J45: 0.1 | K45: 13.8 | L45: 0.7
A46: TOTAL | H46: =SUM(H42:H45) -> 251.5 | I46: =SUM(I42:I45) -> 11.7 | J46: =SUM(J42:J45) -> 9.9 | K46: =SUM(K42:K45) -> 30.3 | L46: =SUM(L42:L45) -> 2.7
A47: 30 % KEBUTUHAN HARIAN | H47: 668 | I47: 20.3 | J47: 22.5 | K47: 97.5 | L47: 10
...

Sheet B3 12 MARET
A3: MENU
A4: KECIL | B4: BESAR
A5: Goguma Bread 2 | B5: Goguma Bread 2 | L5: PENERIMA MANFAAT
A6: Telur ayam rebus 2 | B6: Telur ayam rebus 2 | L6: PAUD, TK, SD 1 - 3 | M6: 1043
A7: susu 115ml 2 | B7: susu 115ml 2 | L7: SD 4 - 6, SMP, SMA | M7: =1070+253+1 -> 1324
A8: Jeruk 1 | B8: Jeruk 1 | L8: BALITA | M8: 204
A9: lengkeng 4 | B9: lengkeng 4 | L9: IBU | M9: =297+16+1 -> 314
B10: Kurma 10 biji | L10: B3 | M10: =M9+M8 -> 518
L11: PORSI KECIL | M11: =M8+M6 -> 1247
L12: PORSI BESAR | M12: =M7+M9 -> 1638
L13: TOTAL | M13: =SUM(M6:M9) -> 2885
A15: Karbohidrat | C15: Berat Kotor (Gram) | D15: Murid | E15: Total (gram) | F15: Buffer 3% (Gram) | G15: Dalam (Kg) | H15: Satuan | I15: Harga/Satuan | J15: Total
A16: Goguma bread 2 | B16: Roti Lembaran | C16: 2 | D16: 518 | E16: =C16*D16 -> 1036 | F16: =(E16+(E16*4%)) -> 1077.44 | G16: =+F16/1000 -> 1.07744 | H16: Pcs | I16: 1000 | J16: =F16*I16 -> 1077440
B17: Ubi Ungu | C17: 50 | D17: 518 | E17: =C17*D17 -> 25900 | F17: =(E17+(E17*4%)) -> 26936 | G17: =+F17/1000 -> 26.936 | H17: Kg | I17: 13000 | J17: =G17*I17 -> 350168
A18: Protein Hewani | J18: =G18*I18 -> 0
B19: Telur Ayam | C19: =1000/15*2 -> 133.33333 | D19: 518 | E19: =C19*D19 -> 69066.667 | F19: =(E19+(E19*4%)) -> 71829.333 | G19: =+F19/1000 -> 71.829333 | H19: Kg | I19: 32000 | J19: =G19*I19 -> 2298538.7
B20: Susu 225ml | C20: 2 | D20: 518 | E20: =C20*D20 -> 1036 | F20: =(E20+(E20*4%)) -> 1077.44 | G20: =+F20 -> 1077.44 | H20: Pcs | I20: 3500 | J20: =G20*I20 -> 3771040
A21: Protein Nabati | J21: =G21*I21 -> 0
A22: Sayur | J22: =G22*I22 -> 0
A23: Buah | J23: =G23*I23 -> 0
B24: Markisa | C24: 1 | D24: 518 | E24: =C24*D24 -> 518 | F24: =(E24+(E24*3%)) -> 533.54 | G24: =+F24 -> 533.54 | H24: Pcs
B25: Jeruk | C25: 2 | D25: 518 | E25: =C25*D25 -> 1036 | F25: =(E25+(E25*3%)) -> 1067.08 | G25: =+F25 -> 1067.08 | H25: Pcs | I25: 2300 | J25: =G25*I25 -> 2454284
B26: kelengkeng | C26: 40 | D26: 518 | E26: =C26*D26 -> 20720 | F26: =(E26+(E26*3%)) -> 21341.6 | G26: =+F26/1000 -> 21.3416 | H26: Kg | I26: 50000 | J26: =G26*I26 -> 1067080
B27: kurma 10 butir | C27: 110 | D27: 314 | E27: =C27*D27 -> 34540 | F27: =(E27+(E27*3%)) -> 35576.2 | G27: =+F27/1000 -> 35.5762 | H27: Kg | I27: 40000 | J27: =G27*I27 -> 1423048
A28: Lainnya
B29: Susu Kental Manis | C29: 30 | D29: 518 | E29: =C29*D29 -> 15540 | F29: =(E29+(E29*3%)) -> 16006.2 | G29: =F29/1000 -> 16.0062 | H29: liter | I29: 26000 | J29: =K29*I29 -> 416161.2 | K29: =F29/1000 -> 16.0062
B30: Telur | C30: =1000/15/10 -> 6.6666667 | D30: 518 | E30: =C30*D30 -> 3453.3333 | F30: =(E30+(E30*3%)) -> 3556.9333 | G30: =F30/1000 -> 3.5569333 | H30: pcs | I30: 32000 | J30: =K30*I30 -> 113821.87 | K30: =F30/1000 -> 3.5569333
B31: Tepung Panir Putih | C31: 50 | D31: 518 | E31: =C31*D31 -> 25900 | F31: =(E31+(E31*3%)) -> 26677 | G31: =+F31/1000 -> 26.677 | H31: Kg | I31: 18000 | J31: =K31*I31 -> 480186 | K31: =F31/1000 -> 26.677
B32: gula pasir | C32: 3 | D32: 518 | E32: =C32*D32 -> 1554 | F32: =(E32+(E32*3%)) -> 1600.62 | G32: =+F32/1000 -> 1.60062 | H32: Kg | I32: 19000 | J32: =K32*I32 -> 30411.78 | K32: =F32/1000 -> 1.60062
B33: minyak goreng | C33: 10 | D33: 518 | E33: =C33*D33 -> 5180 | F33: =(E33+(E33*3%)) -> 5335.4 | G33: =+F33/1000 -> 5.3354 | H33: Liter | I33: 19500 | J33: =K33*I33 -> 104040.3 | K33: =F33/1000 -> 5.3354
B34: garam | C34: 1 | D34: 518 | E34: =C34*D34 -> 518 | F34: =(E34+(E34*3%)) -> 533.54 | G34: =+F34/1000 -> 0.53354 | H34: Kg | I34: 13000 | J34: =K34*I34 -> 6936.02 | K34: =F34/1000 -> 0.53354
B35: saos tiram | C35: 0.5 | D35: 518 | E35: =C35*D35 -> 259 | F35: =(E35+(E35*3%)) -> 266.77 | G35: =+F35/1000 -> 0.26677 | H35: Kg | I35: 59000 | J35: =K35*I35 -> 15739.43 | K35: =F35/1000 -> 0.26677
B36: Plastik goguma bread | C36: 1 | D36: 518 | E36: =C36*D36 -> 518 | F36: =(E36+(E36*3%)) -> 533.54 | G36: =F36 -> 533.54 | H36: Pcs | J36: =SUM(J16:J35) -> 13608895
B37: plastik kurma | C37: 1 | D37: 518 | E37: =C37*D37 -> 518 | F37: =(E37+(E37*3%)) -> 533.54 | G37: =F37 -> 533.54 | H37: pcs
B38: Mika wadah Utama | C38: 1 | D38: 518 | E38: =C38*D38 -> 518 | F38: =(E38+(E38*3%)) -> 533.54 | G38: =F38 -> 533.54 | H38: Pcs
A42: Kandungan gizi Balita
A43: Bahan Makanan | B43: BDD % | C43: Berat Kotor | D43: Berat Bersih | E43: Faktor Konversi | F43: Penyajian (gr) | G43: URT | H43: Energi | I43: Protein | J43: Lemak | K43: Karbohidrat | L43: Serat
A44: Goguma bread 2 | B44: 100 | C44: 100 | D44: =B44%*C44 -> 100 | E44: 1 | F44: =D44/E44 -> 100 | G44: 2 ptg | H44: 290 | I44: 7 | J44: 10 | K44: 45 | L44: 0
A45: Telur ayam 2 | B45: 87 | C45: =66.7*2 -> 133.4 | D45: =B45*C45% -> 116.058 | E45: 1 | F45: =D45/E45 -> 116.058 | G45: 2 butir | H45: 179 | I45: 14.6 | J45: 12.3 | K45: 1.9 | L45: 0
A46: susu 115ml 2 | B46: 100 | C46: =115*2 -> 230 | D46: =B46%*C46 -> 230 | E46: 1 | F46: =D46/E46 -> 230 | G46: 2 kotak kecil | H46: 140 | I46: 6 | J46: 7 | K46: 12 | L46: 0
...

Sheet 13-14 MARET
A1: 1
A3: MENU
A4: KECIL | B4: BESAR | L4: PENERIMA MANFAAT
A5: Roti 1 | B5: Roti 1 | L5: PAUD, TK, SD 1 - 3 | M5: 1043
A6: Ayam ungkep | B6: Ayam ungkep | L6: SD 4 - 6, SMP, SMA | M6: =1070+253+1 -> 1324
A7: Jeruk | B7: Jeruk | L7: BALITA | M7: 204
B8: Kurma 6 biji | L8: IBU | M8: =297+16+1 -> 314
L9: B3 | M9: =M8+M7 -> 518
L10: PORSI KECIL | M10: =M7+M5 -> 1247
L11: PORSI BESAR | M11: =M6+M8 -> 1638
L12: TOTAL | M12: =SUM(M5:M8) -> 2885
A15: Karbohidrat | C15: Berat Kotor (Gram) | D15: Murid | E15: Total (gram) | F15: Buffer 3% (Gram) | G15: Dalam (Kg) | H15: Satuan | I15: Harga/Satuan | J15: Total
B16: Roti | C16: 1 | D16: 2367 | E16: =C16*D16 -> 2367 | F16: =(E16+(E16*3%)) -> 2438.01 | G16: =F16 -> 2438.01 | H16: pcs | I16: 2200 | J16: =G16*I16 -> 5363622
A17: Protein Hewani | J17: =G17*I17 -> 0
A18: Porsi Kecil | B18: Ayam 1kg 12 | C18: =1000/12*2 -> 166.66667 | D18: 1043 | E18: =C18*D18 -> 173833.33 | F18: =(E18+(E18*4%)) -> 180786.67 | G18: =+F18/1000 -> 180.78667 | H18: Kg | I18: 40000 | J18: =G18*I18 -> 7231466.7 | K18: =G18+G19 -> 456.17867
A19: Porsi Besar | B19: Ayam 1kg 10 | C19: =1000/10*2 -> 200 | D19: 1324 | E19: =C19*D19 -> 264800 | F19: =(E19+(E19*4%)) -> 275392 | G19: =+F19/1000 -> 275.392 | H19: Kg | I19: 40000 | J19: =G19*I19 -> 11015680
A20: Protein Nabati | J20: =G20*I20 -> 0
A21: Sayur | J21: =G21*I21 -> 0
A22: Buah | J22: =G22*I22 -> 0
B23: Jeruk | C23: 1 | D23: 2367 | E23: =D23*C23 -> 2367 | F23: =(E23+(E23*3%)) -> 2438.01 | G23: =F23 -> 2438.01 | H23: Kg | I23: 2500 | J23: =G23*I23 -> 6095025
B24: kurma 6 | C24: 66 | D24: 1324 | E24: =C24*D24 -> 87384 | F24: =(E24+(E24*3%)) -> 90005.52 | G24: =+F24/1000 -> 90.00552 | H24: Kg | I24: 40000 | J24: =G24*I24 -> 3600220.8
A25: Lainnya
B26: kunyit utuh | C26: 1 | D26: 2367 | E26: =C26*D26 -> 2367 | F26: =(E26+(E26*3%)) -> 2438.01 | G26: =+F26/1000 -> 2.43801 | H26: Kg | I26: 15000 | J26: =K26*I26 -> 36570.15 | K26: =F26/1000 -> 2.43801
B27: jahe utuh | C27: 1 | D27: 2367 | E27: =C27*D27 -> 2367 | F27: =(E27+(E27*3%)) -> 2438.01 | G27: =+F27/1000 -> 2.43801 | H27: Kg | I27: 27000 | J27: =K27*I27 -> 65826.27 | K27: =F27/1000 -> 2.43801
B28: kemiri | C28: 0.5 | D28: 2367 | E28: =C28*D28 -> 1183.5 | F28: =(E28+(E28*3%)) -> 1219.005 | G28: =+F28/1000 -> 1.219005 | H28: Kg | I28: 50000 | J28: =K28*I28 -> 60950.25 | K28: =F28/1000 -> 1.219005
B29: bawang merah kupas | C29: 1.5 | D29: 2367 | E29: =C29*D29 -> 3550.5 | F29: =(E29+(E29*3%)) -> 3657.015 | G29: =+F29/1000 -> 3.657015 | H29: Kg | I29: 45000 | J29: =K29*I29 -> 164565.67 | K29: =F29/1000 -> 3.657015
B30: bawang putih kupas | C30: 1.5 | D30: 2367 | E30: =C30*D30 -> 3550.5 | F30: =(E30+(E30*3%)) -> 3657.015 | G30: =+F30/1000 -> 3.657015 | H30: Kg | I30: 43000 | J30: =K30*I30 -> 157251.64 | K30: =F30/1000 -> 3.657015
B31: ketumbar bubuk | C31: 0.5 | D31: 2367 | E31: =C31*D31 -> 1183.5 | F31: =(E31+(E31*3%)) -> 1219.005 | G31: =+F31/1000 -> 1.219005 | H31: Kg | I31: 35000 | J31: =K31*I31 -> 42665.175 | K31: =F31/1000 -> 1.219005
B32: garam | C32: 3 | D32: 2367 | E32: =C32*D32 -> 7101 | F32: =(E32+(E32*3%)) -> 7314.03 | G32: =+F32/1000 -> 7.31403 | H32: Kg | I32: 13000 | J32: =K32*I32 -> 95082.39 | K32: =F32/1000 -> 7.31403
B33: knor ayam | C33: 1 | D33: 2367 | E33: =C33*D33 -> 2367 | F33: =(E33+(E33*3%)) -> 2438.01 | G33: =+F33/1000 -> 2.43801 | H33: Kg | I33: 102000 | J33: =K33*I33 -> 248677.02 | K33: =F33/1000 -> 2.43801
B34: gula pasir | C34: 3 | D34: 2367 | E34: =C34*D34 -> 7101 | F34: =(E34+(E34*3%)) -> 7314.03 | G34: =+F34/1000 -> 7.31403 | H34: Kg | I34: 19000 | J34: =K34*I34 -> 138966.57 | K34: =F34/1000 -> 7.31403
B35: miwon | C35: 1 | D35: 2367 | E35: =C35*D35 -> 2367 | F35: =(E35+(E35*3%)) -> 2438.01 | G35: =+F35/1000 -> 2.43801 | H35: Kg | I35: 53000 | J35: =K35*I35 -> 129214.53 | K35: =F35/1000 -> 2.43801
B36: minyak goreng | C36: 20 | D36: 2367 | E36: =C36*D36 -> 47340 | F36: =(E36+(E36*3%)) -> 48760.2 | G36: =+F36/1000 -> 48.7602 | H36: Liter | I36: 19500 | J36: =K36*I36 -> 950823.9 | K36: =F36/1000 -> 48.7602
B37: daun salam | C37: 0.5 | D37: 2367 | E37: =C37*D37 -> 1183.5 | F37: =(E37+(E37*3%)) -> 1219.005 | G37: =+F37/1000 -> 1.219005 | H37: Kg | I37: 16000 | J37: =K37*I37 -> 19504.08 | K37: =F37/1000 -> 1.219005
B38: Sereh | C38: 0.5 | D38: 2367 | E38: =C38*D38 -> 1183.5 | F38: =(E38+(E38*3%)) -> 1219.005 | G38: =+F38/1000 -> 1.219005 | H38: Kg | I38: 17000 | J38: =K38*I38 -> 20723.085 | K38: =F38/1000 -> 1.219005
B39: sausa tiram panda | C39: 0.5 | D39: 2367 | E39: =C39*D39 -> 1183.5 | F39: =(E39+(E39*3%)) -> 1219.005 | G39: =F39/1000 -> 1.219005 | H39: Liter | I39: 59000 | J39: =K39*I39 -> 71921.295 | K39: =F39/1000 -> 1.219005
B40: plastik ayam goreng | C40: 1 | D40: 2367 | E40: =C40*D40 -> 2367 | F40: =(E40+(E40*3%)) -> 2438.01 | G40: =F40 -> 2438.01 | H40: pcs | J40: =SUM(J16:J39) -> 35508757
B41: plastik kurma | C41: 1 | D41: 1324 | E41: =C41*D41 -> 1324 | F41: =(E41+(E41*3%)) -> 1363.72 | G41: =F41 -> 1363.72 | H41: pcs
B42: mika wadah utama | C42: 1 | D42: 2367 | E42: =C42*D42 -> 2367 | F42: =(E42+(E42*3%)) -> 2438.01 | G42: =F42 -> 2438.01 | H42: pcs
A45: Kandungan gizi TK dan SD 1-3
...

Sheet 14 MARET
A1: SABTU | C1: 46081 | E1: ANAK SEKOLAH | L1: Kandungan gizi TK dan SD 1-3
L2: Bahan Makanan | M2: BDD % | N2: Berat Kotor | O2: Berat Bersih | P2: Faktor Konversi | Q2: Penyajian (gr) | R2: URT | S2: Energi | T2: Protein | U2: Lemak | V2: Karbohidrat | W2: Serat
A3: MENU
A4: KECIL | B4: BESAR
A5: roti | B5: roti
A6: sari kacang hijau 1 | B6: sari kacang hijau 1
A7: telur puyuh 30gr | B7: telur puyuh 30gr
B8: Kurma 35gr
C10: Berat Kotor (Gram) | D10: Murid | E10: Total (gram) | F10: Buffer 3% (Gram) | G10: Dalam (Kg) | H10: Satuan | I10: Harga/Satuan | J10: Total | L10: TOTAL | S10: =SUM(S3:S9) -> 0 | T10: =SUM(T3:T9) -> 0 | U10: =SUM(U3:U9) -> 0 | V10: =SUM(V3:V9) -> 0 | W10: =SUM(W3:W9) -> 0
B11: roti | C11: 1 | D11: 2367 | E11: =C11*D11 -> 2367 | F11: =(E11+(E11*3%)) -> 2438.01 | G11: =F11 -> 2438.01 | H11: pcs | I11: 2200 | J11: =G11*I11 -> 5363622 | L11: 20 % KEBUTUHAN HARIAN | S11: 330 | T11: 8 | U11: 11 | V11: 50 | W11: 4
B12: Sari Kacang Hijau | C12: 1 | D12: 2367 | E12: =C12*D12 -> 2367 | F12: =(E12+(E12*3%)) -> 2438.01 | G12: =+F12 -> 2438.01 | H12: Pcs | I12: 2300 | J12: =G12*I12 -> 5607423 | L12: % KECUKUPAN GIZI | S12: =(S10/S11)*100 -> 0 | T12: =(T10/T11)*100 -> 0 | U12: =(U10/U11)*100 -> 0 | V12: =(V10/V11)*100 -> 0 | W12: =(W10/W11)*100 -> 0
B13: telur puyuh 30gr | C13: 30 | D13: 2367 | E13: =C13*D13 -> 71010 | F13: =(E13+(E13*3%)) -> 73140.3 | G13: =+F13/1000 -> 73.1403 | H13: Kg | I13: 42000 | J13: =G13*I13 -> 3071892.6
B14: kelengkeng | C14: 40 | D14: 2367 | E14: =C14*D14 -> 94680 | F14: =(E14+(E14*3%)) -> 97520.4 | G14: =F14/1000 -> 97.5204 | H14: kg | I14: 50000 | J14: =G14*I14 -> 4876020
B15: Kurma 35gr | C15: 35 | D15: 1324 | E15: =C15*D15 -> 46340 | F15: =(E15+(E15*3%)) -> 47730.2 | G15: =F15/1000 -> 47.7302 | H15: Kg | I15: 40000 | J15: =G15*I15 -> 1909208 | L15: Kandungan gizi SD 4-6 DAN SMP - SMA
B16: Plastik Kurma | C16: 1 | D16: 1324 | E16: =C16*D16 -> 1324 | F16: =(E16+(E16*3%)) -> 1363.72 | G16: =F16 -> 1363.72 | H16: pcs | J16: =SUM(J11:J15) -> 20828166 | L16: Bahan Makanan | M16: BDD % | N16: Berat Kotor | O16: Berat Bersih | P16: Faktor Konversi | Q16: Penyajian (gr) | R16: URT | S16: Energi | T16: Protein | U16: Lemak | V16: Karbohidrat | W16: Serat
B17: Mika wadah utama | C17: 1 | D17: 2367 | E17: =C17*D17 -> 2367 | F17: =(E17+(E17*3%)) -> 2438.01 | G17: =F17 -> 2438.01 | H17: pcs
A19: PENERIMA MANFAAT
A20: PAUD, TK, SD 1 - 3 | B20: 1043
A21: SD 4 - 6, SMP, SMA | B21: =1070+253+1 -> 1324
A22: BALITA | B22: 204
A23: IBU | B23: =297+16+1 -> 314
A24: B3 | B24: =B23+B22 -> 518 | L24: TOTAL | S24: =SUM(S17:S23) -> 0 | T24: =SUM(T17:T23) -> 0 | U24: =SUM(U17:U23) -> 0 | V24: =SUM(V17:V23) -> 0 | W24: =SUM(W17:W23) -> 0
A25: PORSI KECIL | B25: =B22+B20 -> 1247 | L25: 30 % KEBUTUHAN HARIAN | S25: 668 | T25: 20.3 | U25: 22.5 | V25: 97.5 | W25: 10
A26: PORSI BESAR | B26: =B21+B23 -> 1638 | L26: % KECUKUPAN GIZI | S26: =(S24/S25)*100 -> 0 | T26: =(T24/T25)*100 -> 0 | U26: =(U24/U25)*100 -> 0 | V26: =(V24/V25)*100 -> 0 | W26: =(W24/W25)*100 -> 0
A27: TOTAL | B27: =SUM(B20:B23) -> 2885

Sheet Sheet1
A1: LAPORAN ANGGRAN BAHAN BAKU PERIODE
D4: RENCANA
A5: TANGGAL | B5: REALISASI ANGGARAN | D5: NO | E5: KEBUTUHAN | F5: JUMLAH SISWA | G5: ANGGARAN | H5: JUMLAH
B6: ='9 MARET'!J42 -> 20516167 | D6: 1 | E6: Kelas Bawah (Balita - PAUD - TK - SD/MI 1-3 ) | F6: =C39 -> 7482 | G6: 8000 | H6: =F6*G6 -> 59856000
B7: ='10 MARET '!J27 -> 26533109
B8: ='B3 10 MARET'!J47 -> 13304535 | D8: 2 | E8: Kelas Atas ( SD/MI kelas 4 - SMP/MTS - SMA/SMK Kelas 3 - Bumil - Busui) | F8: =D39 -> 9828 | G8: 10000 | H8: =F8*G8 -> 98280000
B9: ='11 MARET'!J43 -> 20930953 | E9: TOTAL | F9: =SUM(F6:F8) -> 17310 | H9: =SUM(H6:H8) -> 158136000
B10: ='12 MARET '!J25 -> 21384095
B11: ='B3 12 MARET'!J36 -> 13608895 | C11: =SUM(B6:B11) -> 1.1627775e+08 | D11: REALISASI
B12: ='13-14 MARET'!J40 -> 35508757 | D12: NO | E12: KEBUTUHAN | F12: JUMLAH SISWA | G12: ANGGARAN | H12: JUMLAH
A13: - | B13: ='14 MARET'!J16 -> 20828166 | C13: 146638750 | D13: 1 | E13: Kelas Bawah (Balita - PAUD - TK - SD/MI 1-3 ) | F13: =C39 -> 7482 | H13: =F13*G13 -> 0
C15: =C11+C13 -> 2.629165e+08 | D15: 2 | E15: Kelas Atas ( SD/MI kelas 4 - SMP/MTS - SMA/SMK Kelas 3 - Bumil - Busui) | F15: =D39 -> 9828 | H15: =F15*G15 -> 0
E16: TOTAL | F16: =SUM(F13:F15) -> 17310 | H16: =SUM(H13:H15) -> 0
A23: TOTAL | B23: =SUM(B6:B22) -> 1.7261468e+08 | C23: =H9-B23 -> -14478675
A25: Penerima manfaat periode 19/08/2025 - 29/08/2025
A26: HARI | B26: TANGGAL | C26: TK,SD 1-3 | D26: SD 4-6, SMP, SMA | E26: JUMLAH SELURUHNYA
A27: Senin | B27: 46090 | C27: 1247 | D27: 1638 | E27: =C27+D27 -> 2885
A28: Selasa | B28: 46091 | C28: 1247 | D28: 1638 | E28: =C28+D28 -> 2885
A29: Rabu | B29: 46092 | C29: 1247 | D29: 1638 | E29: =C29+D29 -> 2885
A30: Kamis | B30: 46093 | C30: 1247 | D30: 1638 | E30: =C30+D30 -> 2885
A31: Jumat | B31: 46094 | C31: 1247 | D31: 1638 | E31: =C31+D31 -> 2885
A32: Sabtu | B32: 46095 | C32: 1247 | D32: 1638 | E32: =C32+D32 -> 2885 | F32: =SUM(E27:E32) -> 17310
A33: Senin | E33: =C33+D33 -> 0
A34: Selasa | E34: =C34+D34 -> 0
A35: Rabu | E35: =C35+D35 -> 0
A36: Kamis | E36: =C36+D36 -> 0
A37: Jumat | E37: =C37+D37 -> 0
A38: Sabtu | E38: =C38+D38 -> 0
C39: =SUM(C27:C38) -> 7482 | D39: =SUM(D27:D38) -> 9828
A40: TOTAL | E40: =SUM(E27:E38) -> 17310 | F40: =E40*3000 -> 51930000
